Workbook

Sheet README
B2: MG-C1 ENERGY TRANSFORMER - BILL OF MATERIALS
B3: Flux-modulated magnetic gear stage (MG-1) driven as a human/low-speed charging generator
B5: Revision | C5: 0.1 - companion to MG-1_drawing_set.pdf (15 sheets) and the MG1_*.scad parametric source
B6: Programme | C6: CBJG LLC · Benchtop Motor Program. SAFE-01 reset semantics per GitHub issue #14 (canonical).
B7: Status | C7: BENCH INSTRUMENT + demonstrator. Not a product. Not for production.
B9: What this builds | C9: A hand-crank (or slow wind / low-head flow) charger. The slow, high-torque input turns the
C10: MG-1 low-speed port; MG-1 steps speed UP 4.5:1 into a low-kV hub motor used as a generator;
C11: a 3-phase bridge, a buck-boost charge controller and a LiFePO4 buffer pack feed a USB-PD port.
B13: Honest headline | C13: ~12 W at the USB-C port at a 90 rpm crank. See the 'Energy budget' tab - it is a live model.
B14: What limits it | C14: NOT the operator. Sustained one-hand cranking is 54 +/- 14 W (Jansen & Slob, 2003).
C15: MG-1's pull-out torque caps mechanical input at ~23 W at 90 rpm. The gear is the bottleneck.
C16: Torque scales with active volume at 12-20 N.m/L, so more power means a physically bigger gear.
B18: No over-unity | C18: P_out <= P_in at all times. Gate 4 (sheet 12) is a MANDATORY falsification test:
C19: three ports measured, cells cross-calibrated and SWAPPED between ports. Required result:
C20: no excess energy. Any reading suggesting otherwise is an instrumentation error, and the
C21: three-port method exists specifically so that error has nowhere to hide.
B23: Build tiers | C23: CHG = everything needed to build and run the charger
C24: INST = adds the three-port instrumentation for Gates 1-4
C25: OPT = variant sweeps (V2/V3 pole pieces), the designed power board, rotary torque sensors
B27: Cost basis | C27: USD, mid-2026, single-unit hobby quantities unless a pack size is stated. Prices move;
C28: the 'Unit cost' column is an input, not a fact. Sources for the researched lines are on
C29: the 'Sources' tab. Freight, tax and contingency rates are assumptions on 'Roll-up'.
B31: Printed parts | C31: Costed by filament mass against a single rate cell on 'Roll-up'. PETG or ASA. NEVER PLA:
C32: PLA creeps at 55 C, a crept air gap is a rotor crash.
B33: Critical BOM note | C33: Line C1 - the 22 pole-piece bolts MUST be plain low-carbon steel. A2/A4 stainless is
C34: austenitic and near-non-magnetic; fit it and the gear makes almost no torque.

Sheet BOM
B2: MG-C1 BILL OF MATERIALS - all line items
B3: Printed-part unit costs are formulas: mass(g)/1000 x the filament rate on Roll-up!C7.
B5: Sect | C5: Ref | D5: Item | E5: Spec / part number | F5: Qty | G5: Unit | H5: Unit cost (USD est.) | I5: Extended (USD) | J5: Tier | K5: Supplier | L5: Notes
B6: A | C6: PRINTED PARTS (PETG or ASA - never PLA)
B7: A | C7: A1 | D7: HS rotor carrier | E7: MG1_rotor.scad, which="hs", 8 thk, d120 | F7: 1 | G7: ea | H7: =95/1000*Roll_up_rate -> 2.09 | I7: =F7*H7 -> 2.09 | J7: CHG | K7: self-printed | L7: 95 g. Pockets UP, 100% infill under pockets.
B8: A | C8: A2 | D8: LS rotor carrier | E8: MG1_rotor.scad, which="ls", 8 thk, d120 | F8: 1 | G8: ea | H8: =95/1000*Roll_up_rate -> 2.09 | I8: =F8*H8 -> 2.09 | J8: CHG | K8: self-printed | L8: 95 g. Metal hub insert or through-pin at the shaft.
B9: A | C9: A3 | D9: Modulator plate + reaction arm | E9: MG1_modulator.scad, variant=1, 12 thk | F9: 1 | G9: ea | H9: =150/1000*Roll_up_rate -> 3.3 | I9: =F9*H9 -> 3.3 | J9: CHG | K9: self-printed | L9: 150 g. Arm SOLID, 6 perimeters - it is a measurement datum.
B10: A | C10: A4 | D10: Frame end plate | E10: MG1_frame.scad, part="frame", 6 thk | F10: 2 | G10: ea | H10: =65/1000*Roll_up_rate -> 1.43 | I10: =F10*H10 -> 2.86 | J10: CHG | K10: self-printed | L10: 65 g each. Bearing seat takes a bonded steel sleeve.
B11: A | C11: A5 | D11: Gap shim, trial only | E11: MG1_frame.scad, part="shim", 0.10 | F11: 6 | G11: ea | H11: =2/1000*Roll_up_rate -> 0.044 | I11: =F11*H11 -> 0.264 | J11: OPT | K11: self-printed | L11: 2 g each. Trial fit only - real sweep uses metal shim stock.
B12: A | C12: A6 | D12: Crank housing + pillow-block mount | E12: derived from frame plate PCD | F12: 1 | G12: set | H12: =180/1000*Roll_up_rate -> 3.96 | I12: =F12*H12 -> 3.96 | J12: CHG | K12: self-printed | L12: 180 g.
B13: A | C13: A7 | D13: Burst shroud frame | E13: holds the polycarbonate window | F13: 1 | G13: ea | H13: =120/1000*Roll_up_rate -> 2.64 | I13: =F13*H13 -> 2.64 | J13: CHG | K13: self-printed | L13: 120 g. Interlock switch pocket moulded in.
B14: A | C14: A8 | D14: Assembly jig plates | E14: threaded-rod walk-in jig, sheet 3 step 7 | F14: 2 | G14: ea | H14: =30/1000*Roll_up_rate -> 0.66 | I14: =F14*H14 -> 1.32 | J14: CHG | K14: self-printed | L14: 60 g total.
B15: A | C15: A9 | D15: Generator mount cradle | E15: 6.5in hub motor stator clamp | F15: 1 | G15: ea | H15: =140/1000*Roll_up_rate -> 3.08 | I15: =F15*H15 -> 3.08 | J15: CHG | K15: self-printed | L15: 140 g.
B17: B | C17: MAGNETS & BONDING
B18: B | C18: B1 | D18: Neodymium block magnet | E18: N42 nickel, 20 x 10 x 5 mm, Q-20-10-05-N | F18: 45 | G18: ea | H18: 1.4 | I18: =F18*H18 -> 63 | J18: CHG | K18: supermagnete | L18: 38 used (20 HS + 18 LS) + 7 spares. EUR1.26 ea from 40 pcs.
B19: B | C19: B2 | D19: Magnet keeper / storage box | E19: steel-lined, separated cells | F19: 1 | G19: ea | H19: 8 | I19: =F19*H19 -> 8 | J19: CHG | K19: generic | L19: Loose N42 blocks are projectiles. Store separated.
B20: B | C20: B3 | D20: Cyanoacrylate, thick gel | E20: 20 g | F20: 2 | G20: ea | H20: 7 | I20: =F20*H20 -> 14 | J20: CHG | K20: generic | L20: Seat DRY and probe polarity BEFORE any adhesive.
B21: B | C21: B4 | D21: CA activator | E21: 150 ml | F21: 1 | G21: ea | H21: 8 | I21: =F21*H21 -> 8 | J21: CHG | K21: generic
B22: B | C22: B5 | D22: Isopropyl alcohol | E22: 500 ml, pocket prep | F22: 1 | G22: ea | H22: 6 | I22: =F22*H22 -> 6 | J22: CHG | K22: generic
B24: C | C24: GAP-CRITICAL METAL, FASTENERS & SHAFTING
B25: C | C25: C1 | D25: Pole-piece bolt | E25: M8 x 25, grade 4.8 LOW-CARBON STEEL, plain | F25: 26 | G25: ea | H25: 0.35 | I25: =F25*H25 -> 9.1 | J25: CHG | K25: fastener supplier | L25: CRITICAL: must be magnetic plain steel. A2/A4 stainless is austenitic and near-non-magnetic - it will produce almost zero torque.
B26: C | C26: C2 | D26: M8 flat washer | E26: plain steel | F26: 26 | G26: ea | H26: 0.05 | I26: =F26*H26 -> 1.3 | J26: CHG | K26: fastener supplier
B27: C | C27: C3 | D27: Tie rod stock | E27: M5 x 1000 threaded rod, A2 stainless | F27: 1 | G27: ea | H27: 6 | I27: =F27*H27 -> 6 | J27: CHG | K27: fastener supplier | L27: Cut 4 x 53.6 mm. Stainless is fine here - it sits outside the flux path.
B28: C | C28: C4 | D28: M5 nyloc nut | E28: A2 | F28: 16 | G28: ea | H28: 0.12 | I28: =F28*H28 -> 1.92 | J28: CHG | K28: fastener supplier
B29: C | C29: C5 | D29: Aluminium standoff tube | E29: 9.0 OD x 5.3 ID x 300 mm | F29: 1 | G29: ea | H29: 9 | I29: =F29*H29 -> 9 | J29: CHG | K29: metal supplier | L29: Cut 4 x 41.6 mm. THESE set the two 0.80 mm air gaps, not the plastic.
B30: C | C30: C6 | D30: Deep-groove ball bearing | E30: 608ZZ, 8 x 22 x 7, 10-pack | F30: 1 | G30: pk | H30: 20.65 | I30: =F30*H30 -> 20.65 | J30: CHG | K30: Amazon (NSK) | L30: 4 used, 6 spare. USD2.07 each.
B31: C | C31: C7 | D31: Steel bearing sleeve | E31: 22.0 OD, 1.2 wall, 30 mm long | F31: 2 | G31: ea | H31: 12 | I31: =F31*H31 -> 24 | J31: CHG | K31: metal supplier | L31: Bonded into the printed seat. NEVER run a 608 directly in plastic.
B32: C | C32: C8 | D32: Ground shaft | E32: d8 h6 x 100 mm, 1045 or stainless | F32: 2 | G32: ea | H32: 7 | I32: =F32*H32 -> 14 | J32: CHG | K32: metal supplier | L32: HS shaft to generator, LS shaft to crank.
B33: C | C33: C9 | D33: Key steel | E33: 3 x 3 x 100 mm | F33: 1 | G33: ea | H33: 4 | I33: =F33*H33 -> 4 | J33: CHG | K33: metal supplier
B34: C | C34: C10 | D34: Shim stock assortment | E34: brass/steel 0.05-0.20 mm | F34: 1 | G34: set | H34: 12 | I34: =F34*H34 -> 12 | J34: CHG | K34: metal supplier | L34: The real Gate 1 gap sweep: 0.60/0.80/1.00/1.20.
B35: C | C35: C11 | D35: M3 mild steel rod | E35: 3 mm x 1 m, for V2 bundled pole pieces | F35: 1 | G35: ea | H35: 5 | I35: =F35*H35 -> 5 | J35: OPT | K35: metal supplier | L35: V2 variant: 11 x 7-off M3 bundles, ~7x lower eddy loss.
B36: C | C36: C12 | D36: Laminated steel sheet | E36: 0.35 mm, 100 x 100, for V3 pole pieces | F36: 1 | G36: ea | H36: 18 | I36: =F36*H36 -> 18 | J36: OPT | K36: metal supplier | L36: V3 variant: stacked laminations, approaches literature loss.
B38: D | C38: DRIVE, CRANK, GENERATOR & GUARDING
B39: D | C39: D1 | D39: Hub motor used as PMSG | E39: 6.5in hoverboard hub motor, 36 V 250 W class | F39: 1 | G39: ea | H39: 106.99 | I39: =F39*H39 -> 106.99 | J39: CHG | K39: Monster Scooter Parts | L39: kV ~13.4 rpm/V from vehicle data - very low kV is exactly what a slow charger needs. AliExpress ~USD70 alternative.
B40: D | C40: D2 | D40: Hand crank arm | E40: 150 mm, rotating knob, d8 bore | F40: 1 | G40: ea | H40: 14 | I40: =F40*H40 -> 14 | J40: CHG | K40: generic | L40: 150 mm x 16 N of hand force = 2.4 N.m, the design point.
B41: D | C41: D3 | D41: Pillow block bearing | E41: KFL08 flange, d8 | F41: 2 | G41: ea | H41: 6 | I41: =F41*H41 -> 12 | J41: CHG | K41: generic | L41: Carries crank side load off the printed plate.
B42: D | C42: D4 | D42: Flexible jaw coupling | E42: 8 mm - 8 mm, backlash-free | F42: 2 | G42: ea | H42: 8 | I42: =F42*H42 -> 16 | J42: CHG | K42: generic | L42: Isolates shaft misalignment from the air gap.
B43: D | C43: D5 | D43: Aluminium extrusion | E43: 2020 T-slot, 1 m | F43: 2 | G43: ea | H43: 9 | I43: =F43*H43 -> 18 | J43: CHG | K43: generic | L43: Bench frame.
B44: D | C44: D6 | D44: Bracket + T-nut set | E44: 2020 corner brackets, M5 | F44: 1 | G44: set | H44: 14 | I44: =F44*H44 -> 14 | J44: CHG | K44: generic
B45: D | C45: D7 | D45: Polycarbonate sheet | E45: 3 mm, 300 x 300, burst shroud window | F45: 1 | G45: ea | H45: 18 | I45: =F45*H45 -> 18 | J45: CHG | K45: plastics supplier | L45: PC, not acrylic. Acrylic shatters.
...

Sheet Roll-up
B2: COST ROLL-UP
B4: Assumptions
B5: Filament rate | C5: $/kg | D5: 22 | G5: PETG, 1 kg spool. Drives every printed-part unit cost.
B6: Freight | C6: % of subtotal | D6: 0.08 | G6: Many small suppliers; assume 8%.
B7: Sales tax | C7: % of subtotal | D7: 0.0825 | G7: TX combined rate assumed - VERIFY for your address.
B8: Contingency | C8: % of subtotal | D8: 0.12 | G8: Reprints, one cooked module, a shorted FET.
B9: EUR to USD | C9: rate | D9: 1.09 | G9: Used for the supermagnete magnet price.
B12: Subtotal by section
B13: A PRINTED PARTS (PETG or ASA - never PLA) | D13: =SUMIFS(BOM!$I$6:$I$97,BOM!$B$6:$B$97,"A") -> 21.604
B14: B MAGNETS & BONDING | D14: =SUMIFS(BOM!$I$6:$I$97,BOM!$B$6:$B$97,"B") -> 99
B15: C GAP-CRITICAL METAL, FASTENERS & SHAFTING | D15: =SUMIFS(BOM!$I$6:$I$97,BOM!$B$6:$B$97,"C") -> 124.97
B16: D DRIVE, CRANK, GENERATOR & GUARDING | D16: =SUMIFS(BOM!$I$6:$I$97,BOM!$B$6:$B$97,"D") -> 214.99
B17: E ENERGY TRANSFORMER - POWER CONVERSION CHAIN | D17: =SUMIFS(BOM!$I$6:$I$97,BOM!$B$6:$B$97,"E") -> 192.6
B18: F INSTRUMENTATION (Gates 1-4, three-port energy balance) | D18: =SUMIFS(BOM!$I$6:$I$97,BOM!$B$6:$B$97,"F") -> 660
B19: G CONSUMABLES, TOOLING & SAFETY | D19: =SUMIFS(BOM!$I$6:$I$97,BOM!$B$6:$B$97,"G") -> 271
B20: ALL LINE ITEMS | D20: =SUM(D13:D19) -> 1584.164
B23: Build tiers
B24: Tier | C24: Scope | D24: Hardware subtotal | E24: + freight & tax | F24: + contingency | G24: DELIVERED TOTAL | H24: What you get
B25: 1 | C25: CHARGER | D25: =SUMIFS(BOM!$I$6:$I$97,BOM!$J$6:$J$97,"CHG") -> 846.7 | E25: =D25*(1+$D$6+$D$7) -> 984.28875 | F25: =E25+D25*$D$8 -> 1085.8927 | G25: =F25 -> 1085.8927 | H25: Working charger: prints, magnets, metal stack, generator, crank, guarding, power chain, core tooling.
B26: 2 | C26: INSTRUMENTED | D26: =SUMIFS(BOM!$I$6:$I$97,BOM!$J$6:$J$97,"CHG")+SUMIFS(BOM!$I$6:$I$97,BOM!$J$6:$J$97,"INST") -> 986.7 | E26: =D26*(1+$D$6+$D$7) -> 1147.0387 | F26: =E26+D26*$D$8 -> 1265.4427 | G26: =F26 -> 1265.4427 | H26: Adds three-port sensing, encoders, logging and dead-weight calibration - Gates 1-4 become runnable.
B27: 3 | C27: FULL RESEARCH | D27: =SUMIFS(BOM!$I$6:$I$97,BOM!$J$6:$J$97,"CHG")+SUMIFS(BOM!$I$6:$I$97,BOM!$J$6:$J$97,"INST")+SUMIFS(BOM!$I$6:$I$97,BOM!$J$6:$J$97,"OPT") -> 1584.164 | E27: =D27*(1+$D$6+$D$7) -> 1841.5907 | F27: =E27+D27*$D$8 -> 2031.6903 | G27: =F27 -> 2031.6903 | H27: Adds V2/V3 pole-piece sweep, the LTC4020/LT4320 designed board, and rotary torque sensors.
B30: Note | C30: Tier 3 is dominated by ONE line: F2, the pair of rotary torque sensors. Start on Tier 2 load cells, upgrade at Gate 3 only if the load-cell uncertainty band is too wide to close the energy balance.

Sheet Energy budget
B2: ENERGY BUDGET - live model
B3: Change the blue input cells. Everything else is a formula. No hardcoded results.
B4: Inputs
B5: Crank torque at LS port | C5: N.m | D5: 2.4 | H5: Design point. 150 mm crank arm x ~16 N of hand force.
B6: Crank speed at LS port | C6: rpm | D6: 90 | H6: Comfortable sustained one-hand cranking band is 60-120 rpm.
B7: Gear ratio |G| | C7: - | D7: 4.5 | H7: p_out/p_in = 9/2. Counter-rotating.
B8: Generator kV | C8: rpm/V | D8: 13.4 | H8: 6.5in hub motor, derived from 165 mm wheel at ~15 km/h on 36 V.
B9: MG-1 LS pull-out, low | C9: N.m | D9: 1.8 | H9: 12 N.m/L on 0.150 L active volume.
B10: MG-1 LS pull-out, high | C10: N.m | D10: 3 | H10: 20 N.m/L on 0.150 L active volume.
B12: Derived operating point
B13: LS angular velocity | C13: rad/s | D13: =2*PI()*D6/60 -> 9.424778
B14: Mechanical input power | C14: W | D14: =D5*D13 -> 22.619467 | H14: tau x omega at the crank. THIS is the ceiling, not the operator.
B15: HS shaft speed | C15: rpm | D15: =D6*D7 -> 405 | H15: Into the generator.
B16: HS shaft torque | C16: N.m | D16: =D5/D7 -> 0.53333333
B17: Generator line back-EMF | C17: V | D17: =D15/D8 -> 30.223881 | H17: Sets the rectifier and buck-boost input window.
B18: Modulator field frequency | C18: Hz | D18: =550*D15/3000 -> 74.25 | H18: 550 Hz at 3000 rpm HS scales linearly with speed.
B19: Eddy loss vs rated speed | C19: x | D19: =(D18/550)^2 -> 0.018225 | H19: Loss scales as f^2 - the charger runs in the gear's best loss regime.
B21: Conversion chain
B22: Stage | C22: Efficiency | D22: Loss (W) | E22: Power out (W) | H22: Why this number
B23: Magnetic gear MG-1, V1 solid bolts | C23: 0.9 | D23: =D14*(1-C23) -> 2.2619467 | E23: =D14*C23 -> 20.35752 | H23: At 90 rpm crank the modulator field is only ~74 Hz. Eddy loss scales as f^2, so it is ~1.8% of the rated-speed figure. Bearing and magnet drag dominate here.
B24: Hub motor as PMSG at ~405 rpm | C24: 0.75 | D24: =E23*(1-C24) -> 5.0893801 | E24: =E23*C24 -> 15.26814 | H24: Copper-loss dominated at low speed: back-EMF is small relative to winding resistance. This is the worst stage in the chain.
B25: 3-phase Schottky bridge, ~30 V bus | C25: 0.97 | D25: =E24*(1-C25) -> 0.45804421 | E25: =E24*C25 -> 14.810096 | H25: 2 x 0.4 V drop on a 30 V bus. Swap to LT4320 ideal-diode bridge only if the bus falls below ~10 V.
B26: Buck-boost charge controller | C26: 0.93 | D26: =E25*(1-C26) -> 1.0367067 | E26: =E25*C26 -> 13.773389 | H26: MPPT-style CC/CV into the buffer pack. Module (Tier A) or LTC4020 board (Tier B).
B27: LiFePO4 buffer pack round trip | C27: 0.94 | D27: =E26*(1-C27) -> 0.82640336 | E27: =E26*C27 -> 12.946986 | H27: The cost of decoupling an intermittent source from a device that demands a stable one. Not optional.
B28: USB-PD source stage | C28: 0.93 | D28: =E27*(1-C28) -> 0.90628902 | E28: =E27*C28 -> 12.040697 | H28: 12.8 V pack to 5/9/12 V PD. A real PD source, not a trigger board.
B29: OVERALL | C29: =E28/D14 -> 0.53231568 | D29: =SUM(D23:D28) -> 10.57877 | E29: =E28 -> 12.040697 | H29: Watts delivered at the USB-C port.
B31: What that actually charges
B32: Device | C32: Capacity (Wh) | D32: Cranking hours
B33: Phone, 4000 mAh at 3.85 V | C33: 15.4 | D33: =C33/E29 -> 1.2789957
B34: Tablet | C34: 25 | D34: =C34/E29 -> 2.0762918
B35: 20 000 mAh power bank | C35: 74 | D35: =C35/E29 -> 6.1458236
B36: Laptop, small | C36: 50 | D36: =C36/E29 -> 4.1525835
B38: Output band at the pull-out limits
B39: At LS pull-out low | C39: =D9*2*PI()*D6/60 -> 16.9646 | D39: =C39*C23*C24*C25*C26*C27*C28 -> 9.0305227 | H39: Mechanical W in (col C) -> USB W out (col D). Exceed pull-out and the gear simply slips - it cannot shear a tooth.
B40: At LS pull-out high | C40: =D10*2*PI()*D6/60 -> 28.274334 | D40: =C40*C23*C24*C25*C26*C27*C28 -> 15.050871 | H40: Mechanical W in (col C) -> USB W out (col D). Exceed pull-out and the gear simply slips - it cannot shear a tooth.
B42: Scaling: torque is proportional to active volume at 12-20 N.m/L
B43: Active volume (L) | C43: LS torque low (N.m) | D43: LS torque high (N.m) | E43: Mech W at set rpm, low | F43: Mech W high
B44: 0.15 | C44: =B44*12 -> 1.8 | D44: =B44*20 -> 3 | E44: =C44*2*PI()*D6/60 -> 16.9646 | F44: =D44*2*PI()*D6/60 -> 28.274334
B45: 0.3 | C45: =B45*12 -> 3.6 | D45: =B45*20 -> 6 | E45: =C45*2*PI()*D6/60 -> 33.929201 | F45: =D45*2*PI()*D6/60 -> 56.548668
B46: 0.5 | C46: =B46*12 -> 6 | D46: =B46*20 -> 10 | E46: =C46*2*PI()*D6/60 -> 56.548668 | F46: =D46*2*PI()*D6/60 -> 94.24778
...

Sheet Sources
B2: SOURCES
B3: Researched lines only. Unsourced prices are engineering estimates and are labelled as such.
B5: BOM ref / claim | C5: Source | D5: URL
B6: B1 magnet price and spec | C6: supermagnete Q-20-10-05-N, N42 20x10x5, EUR1.26 ea from 40 pcs | D6: https://www.supermagnete.de/eng/block-magnets-neodymium/block-magnet-20mm-10mm-5mm_Q-20-10-05-N
B7: C6 bearing price | C7: NSK 608ZZ 10-pack, USD20.65 (USD2.07 ea), Amazon | D7: https://www.amazon.com/dp/B07P4NQZ8Q
B8: D1 hub motor price | C8: Hub motor for 6.5in hoverboards, USD106.99, Monster Scooter Parts | D8: https://monsterscooterparts.com/products/hub-motor-for-self-balancing-hoverboards-with-6-5-tires
B9: E3 LT4320 price + spec | C9: Analog Devices LT4320 ideal diode bridge controller, from USD4.07 at 1ku | D9: https://www.analog.com/en/products/lt4320.html
B10: E3 bridge efficiency | C10: LT4320 3-phase demo: 84% for a diode bridge vs 97% for the ideal diode bridge at 5 VAC L-N, 25 A | D10: https://www.analog.com/media/en/technical-documentation/user-guides/dc2465af.pdf
B11: E7 LTC4020 price + spec | C11: Analog Devices LTC4020, 4.5-55 V in, buck-boost multi-chemistry charger, from USD6.79 at 1ku | D11: https://www.analog.com/en/products/ltc4020.html
B12: Human input power | C12: Jansen & Slob, 'Human power: comfortable one-hand cranking', ICED 2003 - sustained 54 +/- 14 W | D12: https://www.designsociety.org/download-publication/23972/human_power_comfortable_one-_hand_cranking
B13: G3 polarity probe | C13: Indigo Instruments Mark II Magnaprobe - confirms magnets are positioned with poles pointing correctly | D13: https://www.indigoinstruments.com/magnets/rare_earth/blocks/ndfeb-block-magnet-20x10x5mm-44251-5.html
B14: Torque density basis | C14: Sheffield PDD thesis: PDD 60-90 N.m/L air-cooled vs 10-30 for conventional PM machines | D14: https://etheses.whiterose.ac.uk/id/eprint/24379/1/PhD_Main_DOC_v64_Final_with_Appendix_corrected.pdf
B15: Gear topology | C15: Atallah & Howe, flux-modulated magnetic gear, J. Magn. Magn. Mater. | D15: https://www.sciencedirect.com/science/article/abs/pii/S0304885303022182
B16: Torque-fuse precedent | C16: Magnomatics Pseudo Direct Drive - inherent torque limit, <60% size/mass of a PM machine | D16: https://www.magnomatics.com/technology/pseudo-direct-drive
